<?xml version="1.0" encoding="utf-8"?>
<!-- This URDF was automatically created by SolidWorks to URDF Exporter! Originally created by Stephen Brawner (brawner@gmail.com) 
     Commit Version: 1.6.0-4-g7f85cfe  Build Version: 1.6.7995.38578
     For more information, please see http://wiki.ros.org/sw_urdf_exporter -->
<robot
  name="WalkBot4Leg.SLDASM">
  <link
    name="Body">
    <inertial>
      <origin
        xyz="-8.19433772981537E-07 -0.00300170877774879 8.17357455831747E-06"
        rpy="0 0 0" />
      <mass
        value="1.03985350556727" />
      <inertia
        ixx="0.00339179073259683"
        ixy="5.51431836645683E-09"
        ixz="3.36188956883992E-10"
        iyy="0.00441758469225806"
        iyz="1.60521989431849E-07"
        izz="0.0013074898058424" />
    </inertial>
    <visual>
      <origin
        xyz="0 0 0"
        rpy="0 0 0" />
      <geometry>
        <mesh
          filename="package://WalkBot4Leg.SLDASM/meshes/Body.STL" />
      </geometry>
      <material
        name="">
        <color
          rgba="0.792156862745098 0.819607843137255 0.933333333333333 1" />
      </material>
    </visual>
    <collision>
      <origin
        xyz="0 0 0"
        rpy="0 0 0" />
      <geometry>
        <mesh
          filename="package://WalkBot4Leg.SLDASM/meshes/Body.STL" />
      </geometry>
    </collision>
  </link>
  <link
    name="FR1_Servo">
    <inertial>
      <origin
        xyz="0.000174801119477846 -0.0318010030269155 6.63024617987423E-05"
        rpy="0 0 0" />
      <mass
        value="0.0230007365895397" />
      <inertia
        ixx="3.38038527155297E-06"
        ixy="2.66636683877537E-09"
        ixz="-8.41838748723445E-11"
        iyy="1.0750315407539E-06"
        iyz="-1.37683480361865E-09"
        izz="2.85194124414614E-06" />
    </inertial>
    <visual>
      <origin
        xyz="0 0 0"
        rpy="0 0 0" />
      <geometry>
        <mesh
          filename="package://WalkBot4Leg.SLDASM/meshes/FR1_Servo.STL" />
      </geometry>
      <material
        name="">
        <color
          rgba="0.792156862745098 0.819607843137255 0.933333333333333 1" />
      </material>
    </visual>
    <collision>
      <origin
        xyz="0 0 0"
        rpy="0 0 0" />
      <geometry>
        <mesh
          filename="package://WalkBot4Leg.SLDASM/meshes/FR1_Servo.STL" />
      </geometry>
    </collision>
  </link>
  <joint
    name="FR1"
    type="revolute">
    <origin
      xyz="-0.05 -0.048856 0.071"
      rpy="0 0 0" />
    <parent
      link="Body" />
    <child
      link="FR1_Servo" />
    <axis
      xyz="0 0 1" />
    <limit
      lower="-1.5708"
      upper="1.5708"
      effort="0.52"
      velocity="10.89" />
  </joint>
  <link
    name="FR2_Servo">
    <inertial>
      <origin
        xyz="0.000235907986100486 -0.0319962115408566 9.42397503334025E-06"
        rpy="0 0 0" />
      <mass
        value="0.0226043083522871" />
      <inertia
        ixx="3.27436167088692E-06"
        ixy="2.66811008456557E-09"
        ixz="-8.29162619228917E-11"
        iyy="1.11333471633781E-06"
        iyz="-1.37858113386786E-09"
        izz="2.83878279589868E-06" />
    </inertial>
    <visual>
      <origin
        xyz="0 0 0"
        rpy="0 0 0" />
      <geometry>
        <mesh
          filename="package://WalkBot4Leg.SLDASM/meshes/FR2_Servo.STL" />
      </geometry>
      <material
        name="">
        <color
          rgba="0.792156862745098 0.819607843137255 0.933333333333333 1" />
      </material>
    </visual>
    <collision>
      <origin
        xyz="0 0 0"
        rpy="0 0 0" />
      <geometry>
        <mesh
          filename="package://WalkBot4Leg.SLDASM/meshes/FR2_Servo.STL" />
      </geometry>
    </collision>
  </link>
  <joint
    name="FR2"
    type="revolute">
    <origin
      xyz="0 -0.047416 0"
      rpy="0 0 0" />
    <parent
      link="FR1_Servo" />
    <child
      link="FR2_Servo" />
    <axis
      xyz="-1 0 0" />
    <limit
      lower="-1.5708"
      upper="1.5708"
      effort="0.52"
      velocity="10.89" />
  </joint>
  <link
    name="FR3_Servo">
    <inertial>
      <origin
        xyz="8.14892709388171E-05 -0.0246574562466224 2.80851153444672E-09"
        rpy="0 0 0" />
      <mass
        value="0.0161002375604621" />
      <inertia
        ixx="1.7994604546192E-06"
        ixy="1.24376477946125E-12"
        ixz="6.8055885449898E-14"
        iyy="1.23532312259261E-06"
        iyz="-1.41793132428333E-13"
        izz="1.4738916006442E-06" />
    </inertial>
    <visual>
      <origin
        xyz="0 0 0"
        rpy="0 0 0" />
      <geometry>
        <mesh
          filename="package://WalkBot4Leg.SLDASM/meshes/FR3_Servo.STL" />
      </geometry>
      <material
        name="">
        <color
          rgba="0.792156862745098 0.819607843137255 0.933333333333333 1" />
      </material>
    </visual>
    <collision>
      <origin
        xyz="0 0 0"
        rpy="0 0 0" />
      <geometry>
        <mesh
          filename="package://WalkBot4Leg.SLDASM/meshes/FR3_Servo.STL" />
      </geometry>
    </collision>
  </link>
  <joint
    name="FR3"
    type="revolute">
    <origin
      xyz="0 -0.047416 0"
      rpy="0 0 0" />
    <parent
      link="FR2_Servo" />
    <child
      link="FR3_Servo" />
    <axis
      xyz="-1 0 0" />
    <limit
      lower="-1.5708"
      upper="1.5708"
      effort="0.52"
      velocity="10.89" />
  </joint>
  <link
    name="FL1_Servo">
    <inertial>
      <origin
        xyz="0.000174801119477846 -0.0318010030269155 6.63024617987423E-05"
        rpy="0 0 0" />
      <mass
        value="0.0230007365895397" />
      <inertia
        ixx="3.38038527155296E-06"
        ixy="2.66636683877604E-09"
        ixz="-8.41838748722806E-11"
        iyy="1.0750315407539E-06"
        iyz="-1.37683480361794E-09"
        izz="2.85194124414614E-06" />
    </inertial>
    <visual>
      <origin
        xyz="0 0 0"
        rpy="0 0 0" />
      <geometry>
        <mesh
          filename="package://WalkBot4Leg.SLDASM/meshes/FL1_Servo.STL" />
      </geometry>
      <material
        name="">
        <color
          rgba="0.792156862745098 0.819607843137255 0.933333333333333 1" />
      </material>
    </visual>
    <collision>
      <origin
        xyz="0 0 0"
        rpy="0 0 0" />
      <geometry>
        <mesh
          filename="package://WalkBot4Leg.SLDASM/meshes/FL1_Servo.STL" />
      </geometry>
    </collision>
  </link>
  <joint
    name="FL1"
    type="revolute">
    <origin
      xyz="0.05 -0.048856 0.071"
      rpy="0 0 0" />
    <parent
      link="Body" />
    <child
      link="FL1_Servo" />
    <axis
      xyz="0 0 1" />
    <limit
      lower="-1.5708"
      upper="1.5708"
      effort="0.52"
      velocity="10.89" />
  </joint>
  <link
    name="FL2_Servo">
    <inertial>
      <origin
        xyz="0.000235907986100507 -0.0319962115408566 9.42397503335413E-06"
        rpy="0 0 0" />
      <mass
        value="0.0226043083522871" />
      <inertia
        ixx="3.27436167088692E-06"
        ixy="2.66811008456652E-09"
        ixz="-8.29162619229834E-11"
        iyy="1.11333471633781E-06"
        iyz="-1.37858113386903E-09"
        izz="2.83878279589868E-06" />
    </inertial>
    <visual>
      <origin
        xyz="0 0 0"
        rpy="0 0 0" />
      <geometry>
        <mesh
          filename="package://WalkBot4Leg.SLDASM/meshes/FL2_Servo.STL" />
      </geometry>
      <material
        name="">
        <color
          rgba="0.792156862745098 0.819607843137255 0.933333333333333 1" />
      </material>
    </visual>
    <collision>
      <origin
        xyz="0 0 0"
        rpy="0 0 0" />
      <geometry>
        <mesh
          filename="package://WalkBot4Leg.SLDASM/meshes/FL2_Servo.STL" />
      </geometry>
    </collision>
  </link>
  <joint
    name="FL2"
    type="revolute">
    <origin
      xyz="0 -0.0474161341528266 0"
      rpy="0 0 0" />
    <parent
      link="FL1_Servo" />
    <child
      link="FL2_Servo" />
    <axis
      xyz="-1 0 0" />
    <limit
      lower="-1.5708"
      upper="1.5708"
      effort="0.52"
      velocity="10.89" />
  </joint>
  <link
    name="FL3_Servo">
    <inertial>
      <origin
        xyz="8.1489270938824E-05 -0.0246574562466224 2.80851153444672E-09"
        rpy="0 0 0" />
      <mass
        value="0.0161002375604621" />
      <inertia
        ixx="1.7994604546192E-06"
        ixy="1.24376477971768E-12"
        ixz="6.80558847330147E-14"
        iyy="1.23532312259261E-06"
        iyz="-1.41793131197445E-13"
        izz="1.4738916006442E-06" />
    </inertial>
    <visual>
      <origin
        xyz="0 0 0"
        rpy="0 0 0" />
      <geometry>
        <mesh
          filename="package://WalkBot4Leg.SLDASM/meshes/FL3_Servo.STL" />
      </geometry>
      <material
        name="">
        <color
          rgba="0.792156862745098 0.819607843137255 0.933333333333333 1" />
      </material>
    </visual>
    <collision>
      <origin
        xyz="0 0 0"
        rpy="0 0 0" />
      <geometry>
        <mesh
          filename="package://WalkBot4Leg.SLDASM/meshes/FL3_Servo.STL" />
      </geometry>
    </collision>
  </link>
  <joint
    name="FL3"
    type="revolute">
    <origin
      xyz="0 -0.0474161341528267 0"
      rpy="0 0 0" />
    <parent
      link="FL2_Servo" />
    <child
      link="FL3_Servo" />
    <axis
      xyz="-1 0 0" />
    <limit
      lower="-1.5708"
      upper="1.5708"
      effort="0.52"
      velocity="10.89" />
  </joint>
  <link
    name="BR1_Servo">
    <inertial>
      <origin
        xyz="0.000174801119477846 -0.0318010030269155 6.63024617987701E-05"
        rpy="0 0 0" />
      <mass
        value="0.0230007365895397" />
      <inertia
        ixx="3.38038527155296E-06"
        ixy="2.66636683877589E-09"
        ixz="-8.41838748724017E-11"
        iyy="1.0750315407539E-06"
        iyz="-1.37683480361918E-09"
        izz="2.85194124414614E-06" />
    </inertial>
    <visual>
      <origin
        xyz="0 0 0"
        rpy="0 0 0" />
      <geometry>
        <mesh
          filename="package://WalkBot4Leg.SLDASM/meshes/BR1_Servo.STL" />
      </geometry>
      <material
        name="">
        <color
          rgba="0.792156862745098 0.819607843137255 0.933333333333333 1" />
      </material>
    </visual>
    <collision>
      <origin
        xyz="0 0 0"
        rpy="0 0 0" />
      <geometry>
        <mesh
          filename="package://WalkBot4Leg.SLDASM/meshes/BR1_Servo.STL" />
      </geometry>
    </collision>
  </link>
  <joint
    name="BR1"
    type="revolute">
    <origin
      xyz="-0.05 -0.048856 -0.071"
      rpy="0 0 0" />
    <parent
      link="Body" />
    <child
      link="BR1_Servo" />
    <axis
      xyz="0 0 1" />
    <limit
      lower="-1.5708"
      upper="1.5708"
      effort="0.52"
      velocity="10.89" />
  </joint>
  <link
    name="BR2_Servo">
    <inertial>
      <origin
        xyz="0.000235907986100507 -0.0319962115408566 9.42397503332637E-06"
        rpy="0 0 0" />
      <mass
        value="0.0226043083522871" />
      <inertia
        ixx="3.27436167088693E-06"
        ixy="2.66811008456744E-09"
        ixz="-8.29162619231932E-11"
        iyy="1.11333471633782E-06"
        iyz="-1.37858113386863E-09"
        izz="2.83878279589868E-06" />
    </inertial>
    <visual>
      <origin
        xyz="0 0 0"
        rpy="0 0 0" />
      <geometry>
        <mesh
          filename="package://WalkBot4Leg.SLDASM/meshes/BR2_Servo.STL" />
      </geometry>
      <material
        name="">
        <color
          rgba="0.792156862745098 0.819607843137255 0.933333333333333 1" />
      </material>
    </visual>
    <collision>
      <origin
        xyz="0 0 0"
        rpy="0 0 0" />
      <geometry>
        <mesh
          filename="package://WalkBot4Leg.SLDASM/meshes/BR2_Servo.STL" />
      </geometry>
    </collision>
  </link>
  <joint
    name="BR2"
    type="revolute">
    <origin
      xyz="0 -0.0474161341528266 0"
      rpy="0 0 0" />
    <parent
      link="BR1_Servo" />
    <child
      link="BR2_Servo" />
    <axis
      xyz="-1 0 0" />
    <limit
      lower="-1.5708"
      upper="1.5708"
      effort="0.52"
      velocity="10.89" />
  </joint>
  <link
    name="BR3_Servo">
    <inertial>
      <origin
        xyz="8.14892709388032E-05 -0.0246574562466224 2.80851152056893E-09"
        rpy="0 0 0" />
      <mass
        value="0.0161002375604621" />
      <inertia
        ixx="1.7994604546192E-06"
        ixy="1.24376478037115E-12"
        ixz="6.80558846872187E-14"
        iyy="1.23532312259261E-06"
        iyz="-1.41793131388506E-13"
        izz="1.4738916006442E-06" />
    </inertial>
    <visual>
      <origin
        xyz="0 0 0"
        rpy="0 0 0" />
      <geometry>
        <mesh
          filename="package://WalkBot4Leg.SLDASM/meshes/BR3_Servo.STL" />
      </geometry>
      <material
        name="">
        <color
          rgba="0.792156862745098 0.819607843137255 0.933333333333333 1" />
      </material>
    </visual>
    <collision>
      <origin
        xyz="0 0 0"
        rpy="0 0 0" />
      <geometry>
        <mesh
          filename="package://WalkBot4Leg.SLDASM/meshes/BR3_Servo.STL" />
      </geometry>
    </collision>
  </link>
  <joint
    name="BR3"
    type="revolute">
    <origin
      xyz="0 -0.0474161341528267 0"
      rpy="0 0 0" />
    <parent
      link="BR2_Servo" />
    <child
      link="BR3_Servo" />
    <axis
      xyz="-1 0 0" />
    <limit
      lower="-1.5708"
      upper="1.5708"
      effort="0.52"
      velocity="10.89" />
  </joint>
  <link
    name="BL1_Servo">
    <inertial>
      <origin
        xyz="0.00017480111947784 -0.0318010030269155 6.63024617987562E-05"
        rpy="0 0 0" />
      <mass
        value="0.0230007365895397" />
      <inertia
        ixx="3.38038527155297E-06"
        ixy="2.66636683877588E-09"
        ixz="-8.41838748722175E-11"
        iyy="1.0750315407539E-06"
        iyz="-1.37683480361878E-09"
        izz="2.85194124414614E-06" />
    </inertial>
    <visual>
      <origin
        xyz="0 0 0"
        rpy="0 0 0" />
      <geometry>
        <mesh
          filename="package://WalkBot4Leg.SLDASM/meshes/BL1_Servo.STL" />
      </geometry>
      <material
        name="">
        <color
          rgba="0.792156862745098 0.819607843137255 0.933333333333333 1" />
      </material>
    </visual>
    <collision>
      <origin
        xyz="0 0 0"
        rpy="0 0 0" />
      <geometry>
        <mesh
          filename="package://WalkBot4Leg.SLDASM/meshes/BL1_Servo.STL" />
      </geometry>
    </collision>
  </link>
  <joint
    name="BL1"
    type="revolute">
    <origin
      xyz="0.05 -0.0488561341528267 -0.071"
      rpy="0 0 0" />
    <parent
      link="Body" />
    <child
      link="BL1_Servo" />
    <axis
      xyz="0 0 1" />
    <limit
      lower="-1.5708"
      upper="1.5708"
      effort="0.52"
      velocity="10.89" />
  </joint>
  <link
    name="BL2_Servo">
    <inertial>
      <origin
        xyz="0.000235907986100521 -0.0319962115408566 9.42397503332637E-06"
        rpy="0 0 0" />
      <mass
        value="0.0226043083522871" />
      <inertia
        ixx="3.27436167088693E-06"
        ixy="2.66811008456582E-09"
        ixz="-8.29162619232281E-11"
        iyy="1.11333471633782E-06"
        iyz="-1.37858113386772E-09"
        izz="2.83878279589868E-06" />
    </inertial>
    <visual>
      <origin
        xyz="0 0 0"
        rpy="0 0 0" />
      <geometry>
        <mesh
          filename="package://WalkBot4Leg.SLDASM/meshes/BL2_Servo.STL" />
      </geometry>
      <material
        name="">
        <color
          rgba="0.792156862745098 0.819607843137255 0.933333333333333 1" />
      </material>
    </visual>
    <collision>
      <origin
        xyz="0 0 0"
        rpy="0 0 0" />
      <geometry>
        <mesh
          filename="package://WalkBot4Leg.SLDASM/meshes/BL2_Servo.STL" />
      </geometry>
    </collision>
  </link>
  <joint
    name="BL2"
    type="revolute">
    <origin
      xyz="0 -0.0474161341528266 0"
      rpy="0 0 0" />
    <parent
      link="BL1_Servo" />
    <child
      link="BL2_Servo" />
    <axis
      xyz="-1 0 0" />
    <limit
      lower="-1.5708"
      upper="1.5708"
      effort="0.52"
      velocity="10.89" />
  </joint>
  <link
    name="BL3_Servo">
    <inertial>
      <origin
        xyz="8.1489270938824E-05 -0.0246574562466224 2.80851154832451E-09"
        rpy="0 0 0" />
      <mass
        value="0.0161002375604621" />
      <inertia
        ixx="1.79946045461919E-06"
        ixy="1.24376477874657E-12"
        ixz="6.80558849416442E-14"
        iyy="1.23532312259261E-06"
        iyz="-1.41793131575549E-13"
        izz="1.47389160064419E-06" />
    </inertial>
    <visual>
      <origin
        xyz="0 0 0"
        rpy="0 0 0" />
      <geometry>
        <mesh
          filename="package://WalkBot4Leg.SLDASM/meshes/BL3_Servo.STL" />
      </geometry>
      <material
        name="">
        <color
          rgba="0.792156862745098 0.819607843137255 0.933333333333333 1" />
      </material>
    </visual>
    <collision>
      <origin
        xyz="0 0 0"
        rpy="0 0 0" />
      <geometry>
        <mesh
          filename="package://WalkBot4Leg.SLDASM/meshes/BL3_Servo.STL" />
      </geometry>
    </collision>
  </link>
  <joint
    name="BL3"
    type="revolute">
    <origin
      xyz="0 -0.0474161341528267 0"
      rpy="0 0 0" />
    <parent
      link="BL2_Servo" />
    <child
      link="BL3_Servo" />
    <axis
      xyz="-1 0 0" />
    <limit
      lower="-1.5708"
      upper="1.5708"
      effort="0.52"
      velocity="10.89" />
  </joint>
</robot>