<?xml version="1.0" encoding="utf-8"?>
<!-- This URDF was automatically created by SolidWorks to URDF Exporter! Originally created by Stephen Brawner (brawner@gmail.com) 
     Commit Version: 1.6.0-4-g7f85cfe  Build Version: 1.6.7995.38578
     For more information, please see http://wiki.ros.org/sw_urdf_exporter -->
<robot
  name="WalkBot4Leg">
  <link
    name="Body">
    <inertial>
      <origin
        xyz="8.17357455831758E-06 -8.19433772982188E-07 -0.00300170877774881"
        rpy="0 0 0" />
      <mass
        value="1.03985350556727" />
      <inertia
        ixx="0.0013074898058424"
        ixy="3.36188956883995E-10"
        ixz="1.6052198943185E-07"
        iyy="0.00339179073259683"
        iyz="5.51431836645647E-09"
        izz="0.00441758469225806" />
    </inertial>
    <visual>
      <origin
        xyz="0 0 0"
        rpy="0 0 0" />
      <geometry>
        <mesh
          filename="package://WalkBot4Leg/meshes/Body.STL" />
      </geometry>
      <material
        name="">
        <color
          rgba="0.792156862745098 0.819607843137255 0.933333333333333 1" />
      </material>
    </visual>
    <collision>
      <origin
        xyz="0 0 0"
        rpy="0 0 0" />
      <geometry>
        <mesh
          filename="package://WalkBot4Leg/meshes/Body.STL" />
      </geometry>
    </collision>
  </link>
  <link
    name="FR1_Servo">
    <inertial>
      <origin
        xyz="6.63024617987423E-05 0.00017480111947784 -0.0318010030269155"
        rpy="0 0 0" />
      <mass
        value="0.0230007365895397" />
      <inertia
        ixx="2.85194124414614E-06"
        ixy="-8.41838748723456E-11"
        ixz="-1.37683480361865E-09"
        iyy="3.38038527155297E-06"
        iyz="2.66636683877568E-09"
        izz="1.0750315407539E-06" />
    </inertial>
    <visual>
      <origin
        xyz="0 0 0"
        rpy="0 0 0" />
      <geometry>
        <mesh
          filename="package://WalkBot4Leg/meshes/FR1_Servo.STL" />
      </geometry>
      <material
        name="">
        <color
          rgba="0.792156862745098 0.819607843137255 0.933333333333333 1" />
      </material>
    </visual>
    <collision>
      <origin
        xyz="0 0 0"
        rpy="0 0 0" />
      <geometry>
        <mesh
          filename="package://WalkBot4Leg/meshes/FR1_Servo.STL" />
      </geometry>
    </collision>
  </link>
  <joint
    name="FR1"
    type="revolute">
    <origin
      xyz="0.071 -0.05 -0.048856"
      rpy="0 0 0" />
    <parent
      link="Body" />
    <child
      link="FR1_Servo" />
    <axis
      xyz="1 0 0" />
    <limit
      lower="-1.5708"
      upper="1.5708"
      effort="0.52"
      velocity="10.89" />
  </joint>
  <link
    name="FR2_Servo">
    <inertial>
      <origin
        xyz="9.42397503328474E-06 0.000235907986100521 -0.0319962115408565"
        rpy="0 0 0" />
      <mass
        value="0.0226043083522871" />
      <inertia
        ixx="2.83878279589868E-06"
        ixy="-8.29162619229471E-11"
        ixz="-1.37858113386998E-09"
        iyy="3.27436167088692E-06"
        iyz="2.66811008456604E-09"
        izz="1.11333471633781E-06" />
    </inertial>
    <visual>
      <origin
        xyz="0 0 0"
        rpy="0 0 0" />
      <geometry>
        <mesh
          filename="package://WalkBot4Leg/meshes/FR2_Servo.STL" />
      </geometry>
      <material
        name="">
        <color
          rgba="0.792156862745098 0.819607843137255 0.933333333333333 1" />
      </material>
    </visual>
    <collision>
      <origin
        xyz="0 0 0"
        rpy="0 0 0" />
      <geometry>
        <mesh
          filename="package://WalkBot4Leg/meshes/FR2_Servo.STL" />
      </geometry>
    </collision>
  </link>
  <joint
    name="FR2"
    type="revolute">
    <origin
      xyz="0 0 -0.047416"
      rpy="0 0 0" />
    <parent
      link="FR1_Servo" />
    <child
      link="FR2_Servo" />
    <axis
      xyz="0 -1 0" />
    <limit
      lower="-1.5708"
      upper="1.5708"
      effort="0.52"
      velocity="10.89" />
  </joint>
  <link
    name="FR3_Servo">
    <inertial>
      <origin
        xyz="2.80851150669115E-09 8.14892709388171E-05 -0.0246574562466224"
        rpy="0 0 0" />
      <mass
        value="0.0161002375604621" />
      <inertia
        ixx="1.4738916006442E-06"
        ixy="6.80558854091741E-14"
        ixz="-1.41793132680958E-13"
        iyy="1.7994604546192E-06"
        iyz="1.24376477956603E-12"
        izz="1.23532312259261E-06" />
    </inertial>
    <visual>
      <origin
        xyz="0 0 0"
        rpy="0 0 0" />
      <geometry>
        <mesh
          filename="package://WalkBot4Leg/meshes/FR3_Servo.STL" />
      </geometry>
      <material
        name="">
        <color
          rgba="0.792156862745098 0.819607843137255 0.933333333333333 1" />
      </material>
    </visual>
    <collision>
      <origin
        xyz="0 0 0"
        rpy="0 0 0" />
      <geometry>
        <mesh
          filename="package://WalkBot4Leg/meshes/FR3_Servo.STL" />
      </geometry>
    </collision>
  </link>
  <joint
    name="FR3"
    type="revolute">
    <origin
      xyz="0 0 -0.0474161341528267"
      rpy="0 0 0" />
    <parent
      link="FR2_Servo" />
    <child
      link="FR3_Servo" />
    <axis
      xyz="0 -1 0" />
    <limit
      lower="-1.5708"
      upper="1.5708"
      effort="0.52"
      velocity="10.89" />
  </joint>
  <link
    name="FL1_Servo">
    <inertial>
      <origin
        xyz="6.63024617987423E-05 0.00017480111947786 -0.0318010030269155"
        rpy="0 0 0" />
      <mass
        value="0.0230007365895397" />
      <inertia
        ixx="2.85194124414614E-06"
        ixy="-8.41838748722835E-11"
        ixz="-1.37683480361837E-09"
        iyy="3.38038527155296E-06"
        iyz="2.66636683877603E-09"
        izz="1.0750315407539E-06" />
    </inertial>
    <visual>
      <origin
        xyz="0 0 0"
        rpy="0 0 0" />
      <geometry>
        <mesh
          filename="package://WalkBot4Leg/meshes/FL1_Servo.STL" />
      </geometry>
      <material
        name="">
        <color
          rgba="0.792156862745098 0.819607843137255 0.933333333333333 1" />
      </material>
    </visual>
    <collision>
      <origin
        xyz="0 0 0"
        rpy="0 0 0" />
      <geometry>
        <mesh
          filename="package://WalkBot4Leg/meshes/FL1_Servo.STL" />
      </geometry>
    </collision>
  </link>
  <joint
    name="FL1"
    type="revolute">
    <origin
      xyz="0.071 0.05 -0.048856"
      rpy="0 0 0" />
    <parent
      link="Body" />
    <child
      link="FL1_Servo" />
    <axis
      xyz="1 0 0" />
    <limit
      lower="-1.5708"
      upper="1.5708"
      effort="0.52"
      velocity="10.89" />
  </joint>
  <link
    name="FL2_Servo">
    <inertial>
      <origin
        xyz="9.42397503331249E-06 0.000235907986100507 -0.0319962115408566"
        rpy="0 0 0" />
      <mass
        value="0.0226043083522871" />
      <inertia
        ixx="2.83878279589868E-06"
        ixy="-8.29162619230321E-11"
        ixz="-1.37858113387105E-09"
        iyy="3.27436167088692E-06"
        iyz="2.66811008456623E-09"
        izz="1.11333471633781E-06" />
    </inertial>
    <visual>
      <origin
        xyz="0 0 0"
        rpy="0 0 0" />
      <geometry>
        <mesh
          filename="package://WalkBot4Leg/meshes/FL2_Servo.STL" />
      </geometry>
      <material
        name="">
        <color
          rgba="0.792156862745098 0.819607843137255 0.933333333333333 1" />
      </material>
    </visual>
    <collision>
      <origin
        xyz="0 0 0"
        rpy="0 0 0" />
      <geometry>
        <mesh
          filename="package://WalkBot4Leg/meshes/FL2_Servo.STL" />
      </geometry>
    </collision>
  </link>
  <joint
    name="FL2"
    type="revolute">
    <origin
      xyz="0 0 -0.0474161341528266"
      rpy="0 0 0" />
    <parent
      link="FL1_Servo" />
    <child
      link="FL2_Servo" />
    <axis
      xyz="0 -1 0" />
    <limit
      lower="-1.5708"
      upper="1.5708"
      effort="0.52"
      velocity="10.89" />
  </joint>
  <link
    name="FL3_Servo">
    <inertial>
      <origin
        xyz="2.80851150669115E-09 8.14892709388101E-05 -0.0246574562466224"
        rpy="0 0 0" />
      <mass
        value="0.0161002375604621" />
      <inertia
        ixx="1.4738916006442E-06"
        ixy="6.80558844491914E-14"
        ixz="-1.41793131288249E-13"
        iyy="1.7994604546192E-06"
        iyz="1.24376477968061E-12"
        izz="1.23532312259261E-06" />
    </inertial>
    <visual>
      <origin
        xyz="0 0 0"
        rpy="0 0 0" />
      <geometry>
        <mesh
          filename="package://WalkBot4Leg/meshes/FL3_Servo.STL" />
      </geometry>
      <material
        name="">
        <color
          rgba="0.792156862745098 0.819607843137255 0.933333333333333 1" />
      </material>
    </visual>
    <collision>
      <origin
        xyz="0 0 0"
        rpy="0 0 0" />
      <geometry>
        <mesh
          filename="package://WalkBot4Leg/meshes/FL3_Servo.STL" />
      </geometry>
    </collision>
  </link>
  <joint
    name="FL3"
    type="revolute">
    <origin
      xyz="0 0 -0.0474161341528267"
      rpy="0 0 0" />
    <parent
      link="FL2_Servo" />
    <child
      link="FL3_Servo" />
    <axis
      xyz="0 -1 0" />
    <limit
      lower="-1.5708"
      upper="1.5708"
      effort="0.52"
      velocity="10.89" />
  </joint>
  <link
    name="BR1_Servo">
    <inertial>
      <origin
        xyz="6.63024617987701E-05 0.00017480111947784 -0.0318010030269155"
        rpy="0 0 0" />
      <mass
        value="0.0230007365895397" />
      <inertia
        ixx="2.85194124414614E-06"
        ixy="-8.41838748724024E-11"
        ixz="-1.37683480361918E-09"
        iyy="3.38038527155296E-06"
        iyz="2.66636683877558E-09"
        izz="1.0750315407539E-06" />
    </inertial>
    <visual>
      <origin
        xyz="0 0 0"
        rpy="0 0 0" />
      <geometry>
        <mesh
          filename="package://WalkBot4Leg/meshes/BR1_Servo.STL" />
      </geometry>
      <material
        name="">
        <color
          rgba="0.792156862745098 0.819607843137255 0.933333333333333 1" />
      </material>
    </visual>
    <collision>
      <origin
        xyz="0 0 0"
        rpy="0 0 0" />
      <geometry>
        <mesh
          filename="package://WalkBot4Leg/meshes/BR1_Servo.STL" />
      </geometry>
    </collision>
  </link>
  <joint
    name="BR1"
    type="revolute">
    <origin
      xyz="-0.071 -0.05 -0.048856"
      rpy="0 0 0" />
    <parent
      link="Body" />
    <child
      link="BR1_Servo" />
    <axis
      xyz="1 0 0" />
    <limit
      lower="-1.5708"
      upper="1.5708"
      effort="0.52"
      velocity="10.89" />
  </joint>
  <link
    name="BR2_Servo">
    <inertial>
      <origin
        xyz="9.42397503334025E-06 0.000235907986100507 -0.0319962115408566"
        rpy="0 0 0" />
      <mass
        value="0.0226043083522871" />
      <inertia
        ixx="2.83878279589868E-06"
        ixy="-8.29162619231961E-11"
        ixz="-1.37858113386865E-09"
        iyy="3.27436167088693E-06"
        iyz="2.66811008456743E-09"
        izz="1.11333471633782E-06" />
    </inertial>
    <visual>
      <origin
        xyz="0 0 0"
        rpy="0 0 0" />
      <geometry>
        <mesh
          filename="package://WalkBot4Leg/meshes/BR2_Servo.STL" />
      </geometry>
      <material
        name="">
        <color
          rgba="0.792156862745098 0.819607843137255 0.933333333333333 1" />
      </material>
    </visual>
    <collision>
      <origin
        xyz="0 0 0"
        rpy="0 0 0" />
      <geometry>
        <mesh
          filename="package://WalkBot4Leg/meshes/BR2_Servo.STL" />
      </geometry>
    </collision>
  </link>
  <joint
    name="BR2"
    type="revolute">
    <origin
      xyz="0 0 -0.0474161341528266"
      rpy="0 0 0" />
    <parent
      link="BR1_Servo" />
    <child
      link="BR2_Servo" />
    <axis
      xyz="0 -1 0" />
    <limit
      lower="-1.5708"
      upper="1.5708"
      effort="0.52"
      velocity="10.89" />
  </joint>
  <link
    name="BR3_Servo">
    <inertial>
      <origin
        xyz="2.80851152056893E-09 8.14892709388032E-05 -0.0246574562466224"
        rpy="0 0 0" />
      <mass
        value="0.0161002375604621" />
      <inertia
        ixx="1.4738916006442E-06"
        ixy="6.80558846871444E-14"
        ixz="-1.41793131387294E-13"
        iyy="1.7994604546192E-06"
        iyz="1.24376478037032E-12"
        izz="1.23532312259261E-06" />
    </inertial>
    <visual>
      <origin
        xyz="0 0 0"
        rpy="0 0 0" />
      <geometry>
        <mesh
          filename="package://WalkBot4Leg/meshes/BR3_Servo.STL" />
      </geometry>
      <material
        name="">
        <color
          rgba="0.792156862745098 0.819607843137255 0.933333333333333 1" />
      </material>
    </visual>
    <collision>
      <origin
        xyz="0 0 0"
        rpy="0 0 0" />
      <geometry>
        <mesh
          filename="package://WalkBot4Leg/meshes/BR3_Servo.STL" />
      </geometry>
    </collision>
  </link>
  <joint
    name="BR3"
    type="revolute">
    <origin
      xyz="0 0 -0.0474161341528267"
      rpy="0 0 0" />
    <parent
      link="BR2_Servo" />
    <child
      link="BR3_Servo" />
    <axis
      xyz="0 -1 0" />
    <limit
      lower="-1.5708"
      upper="1.5708"
      effort="0.52"
      velocity="10.89" />
  </joint>
  <link
    name="BL1_Servo">
    <inertial>
      <origin
        xyz="6.63024617987423E-05 0.000174801119477846 -0.0318010030269155"
        rpy="0 0 0" />
      <mass
        value="0.0230007365895397" />
      <inertia
        ixx="2.85194124414614E-06"
        ixy="-8.41838748722174E-11"
        ixz="-1.37683480361879E-09"
        iyy="3.38038527155297E-06"
        iyz="2.66636683877589E-09"
        izz="1.0750315407539E-06" />
    </inertial>
    <visual>
      <origin
        xyz="0 0 0"
        rpy="0 0 0" />
      <geometry>
        <mesh
          filename="package://WalkBot4Leg/meshes/BL1_Servo.STL" />
      </geometry>
      <material
        name="">
        <color
          rgba="0.792156862745098 0.819607843137255 0.933333333333333 1" />
      </material>
    </visual>
    <collision>
      <origin
        xyz="0 0 0"
        rpy="0 0 0" />
      <geometry>
        <mesh
          filename="package://WalkBot4Leg/meshes/BL1_Servo.STL" />
      </geometry>
    </collision>
  </link>
  <joint
    name="BL1"
    type="revolute">
    <origin
      xyz="-0.071 0.05 -0.0488561341528267"
      rpy="0 0 0" />
    <parent
      link="Body" />
    <child
      link="BL1_Servo" />
    <axis
      xyz="1 0 0" />
    <limit
      lower="-1.5708"
      upper="1.5708"
      effort="0.52"
      velocity="10.89" />
  </joint>
  <link
    name="BL2_Servo">
    <inertial>
      <origin
        xyz="9.42397503332637E-06 0.000235907986100514 -0.0319962115408565"
        rpy="0 0 0" />
      <mass
        value="0.0226043083522871" />
      <inertia
        ixx="2.83878279589868E-06"
        ixy="-8.29162619232249E-11"
        ixz="-1.37858113386771E-09"
        iyy="3.27436167088693E-06"
        iyz="2.66811008456579E-09"
        izz="1.11333471633782E-06" />
    </inertial>
    <visual>
      <origin
        xyz="0 0 0"
        rpy="0 0 0" />
      <geometry>
        <mesh
          filename="package://WalkBot4Leg/meshes/BL2_Servo.STL" />
      </geometry>
      <material
        name="">
        <color
          rgba="0.792156862745098 0.819607843137255 0.933333333333333 1" />
      </material>
    </visual>
    <collision>
      <origin
        xyz="0 0 0"
        rpy="0 0 0" />
      <geometry>
        <mesh
          filename="package://WalkBot4Leg/meshes/BL2_Servo.STL" />
      </geometry>
    </collision>
  </link>
  <joint
    name="BL2"
    type="revolute">
    <origin
      xyz="0 0 -0.0474161341528266"
      rpy="0 0 0" />
    <parent
      link="BL1_Servo" />
    <child
      link="BL2_Servo" />
    <axis
      xyz="0 -1 0" />
    <limit
      lower="-1.5708"
      upper="1.5708"
      effort="0.52"
      velocity="10.89" />
  </joint>
  <link
    name="BL3_Servo">
    <inertial>
      <origin
        xyz="2.80851153444672E-09 8.1489270938824E-05 -0.0246574562466223"
        rpy="0 0 0" />
      <mass
        value="0.0161002375604621" />
      <inertia
        ixx="1.47389160064419E-06"
        ixy="6.8055884941132E-14"
        ixz="-1.41793131575691E-13"
        iyy="1.79946045461919E-06"
        iyz="1.24376477874739E-12"
        izz="1.23532312259261E-06" />
    </inertial>
    <visual>
      <origin
        xyz="0 0 0"
        rpy="0 0 0" />
      <geometry>
        <mesh
          filename="package://WalkBot4Leg/meshes/BL3_Servo.STL" />
      </geometry>
      <material
        name="">
        <color
          rgba="0.792156862745098 0.819607843137255 0.933333333333333 1" />
      </material>
    </visual>
    <collision>
      <origin
        xyz="0 0 0"
        rpy="0 0 0" />
      <geometry>
        <mesh
          filename="package://WalkBot4Leg/meshes/BL3_Servo.STL" />
      </geometry>
    </collision>
  </link>
  <joint
    name="BL3"
    type="revolute">
    <origin
      xyz="0 0 -0.0474161341528267"
      rpy="0 0 0" />
    <parent
      link="BL2_Servo" />
    <child
      link="BL3_Servo" />
    <axis
      xyz="0 -1 0" />
    <limit
      lower="-1.5708"
      upper="1.5708"
      effort="0.52"
      velocity="10.89" />
  </joint>
</robot>