<?xml version="1.0" encoding="utf-8"?>
<!-- This URDF was automatically created by SolidWorks to URDF Exporter! Originally created by Stephen Brawner (brawner@gmail.com) 
     Commit Version: 1.6.0-4-g7f85cfe  Build Version: 1.6.7995.38578
     For more information, please see http://wiki.ros.org/sw_urdf_exporter -->
<robot
  name="WalkBot_3DOF">
  <link
    name="Body">
    <inertial>
      <origin
        xyz="-8.18143322941311E-07 -0.00273725053593522 1.54414926854105E-05"
        rpy="0 0 0" />
      <mass
        value="0.520746828527768" />
      <inertia
        ixx="0.000471200271899893"
        ixy="2.75715917972108E-09"
        ixz="1.68094478399913E-10"
        iyy="0.000983833686042757"
        iyz="5.33273059309758E-09"
        izz="0.000654120958475657" />
    </inertial>
    <visual>
      <origin
        xyz="0 0 0"
        rpy="0 0 0" />
      <geometry>
        <mesh
          filename="../meshes/Body.STL" />
      </geometry>
      <material
        name="">
        <color
          rgba="0.792156862745098 0.819607843137255 0.933333333333333 1" />
      </material>
    </visual>
    <collision>
      <origin
        xyz="0 0 0"
        rpy="0 0 0" />
      <geometry>
        <mesh
          filename="../meshes/Body.STL" />
      </geometry>
    </collision>
  </link>
  <link
    name="Hip_R">
    <inertial>
      <origin
        xyz="0.000174801119477985 -0.0222232795565163 -0.000433697538201265"
        rpy="0 0 0" />
      <mass
        value="0.0230007365895397" />
      <inertia
        ixx="3.38038527155296E-06"
        ixy="2.66636683879314E-09"
        ixz="-8.41838748723652E-11"
        iyy="1.0750315407539E-06"
        iyz="-1.37683480362137E-09"
        izz="2.85194124414613E-06" />
    </inertial>
    <visual>
      <origin
        xyz="0 0 0"
        rpy="0 0 0" />
      <geometry>
        <mesh
          filename="../meshes/Hip_R.STL" />
      </geometry>
      <material
        name="">
        <color
          rgba="0.792156862745098 0.819607843137255 0.933333333333333 1" />
      </material>
    </visual>
    <collision>
      <origin
        xyz="0 0 0"
        rpy="0 0 0" />
      <geometry>
        <mesh
          filename="../meshes/Hip_R.STL" />
      </geometry>
    </collision>
  </link>
  <joint
    name="Hip_R"
    type="revolute">
    <origin
      xyz="-0.05 -0.058127 0.0005"
      rpy="0 0 0" />
    <parent
      link="Body" />
    <child
      link="Hip_R" />
    <axis
      xyz="0 0 1" />
    <limit
      lower="-1.57"
      upper="1.57"
      effort="0.52"
      velocity="10.89" />
  </joint>
  <link
    name="Knee_R">
    <inertial>
      <origin
        xyz="-0.000264092013899299 -0.0224188787501996 9.42397503330609E-06"
        rpy="0 0 0" />
      <mass
        value="0.022604308352287" />
      <inertia
        ixx="3.27436167088692E-06"
        ixy="2.66811008458344E-09"
        ixz="-8.29162619235472E-11"
        iyy="1.11333471633781E-06"
        iyz="-1.37858113387111E-09"
        izz="2.83878279589867E-06" />
    </inertial>
    <visual>
      <origin
        xyz="0 0 0"
        rpy="0 0 0" />
      <geometry>
        <mesh
          filename="../meshes/Knee_R.STL" />
      </geometry>
      <material
        name="">
        <color
          rgba="0.792156862745098 0.819607843137255 0.933333333333333 1" />
      </material>
    </visual>
    <collision>
      <origin
        xyz="0 0 0"
        rpy="0 0 0" />
      <geometry>
        <mesh
          filename="../meshes/Knee_R.STL" />
      </geometry>
    </collision>
  </link>
  <joint
    name="Knee_R"
    type="revolute">
    <origin
      xyz="0.0005 -0.047316 -0.0005"
      rpy="0 0 0" />
    <parent
      link="Hip_R" />
    <child
      link="Knee_R" />
    <axis
      xyz="-1 0 0" />
    <limit
      lower="-1.57"
      upper="1.57"
      effort="0.52"
      velocity="10.89" />
  </joint>
  <link
    name="Ankle_R">
    <inertial>
      <origin
        xyz="-0.000458850309986263 -0.0204363823905408 -1.04380805717468E-11"
        rpy="0 0 0" />
      <mass
        value="0.0318831730757301" />
      <inertia
        ixx="3.0992605738912E-06"
        ixy="1.74478800030802E-12"
        ixz="8.62441036807162E-14"
        iyy="5.54844222417291E-06"
        iyz="-1.54222974317604E-15"
        izz="5.68034830110217E-06" />
    </inertial>
    <visual>
      <origin
        xyz="0 0 0"
        rpy="0 0 0" />
      <geometry>
        <mesh
          filename="../meshes/Ankle_R.STL" />
      </geometry>
      <material
        name="">
        <color
          rgba="0.792156862745098 0.819607843137255 0.933333333333333 1" />
      </material>
    </visual>
    <collision>
      <origin
        xyz="0 0 0"
        rpy="0 0 0" />
      <geometry>
        <mesh
          filename="../meshes/Ankle_R.STL" />
      </geometry>
    </collision>
  </link>
  <joint
    name="Ankle_R"
    type="revolute">
    <origin
      xyz="0 -0.0473161341528267 0"
      rpy="0 0 0" />
    <parent
      link="Knee_R" />
    <child
      link="Ankle_R" />
    <axis
      xyz="-1 0 0" />
    <limit
      lower="-1.57"
      upper="1.57"
      effort="0.52"
      velocity="10.89" />
  </joint>
  <link
    name="Hip_L">
    <inertial>
      <origin
        xyz="0.00017480111947793 -0.0222232795565163 -0.000433697538201265"
        rpy="0 0 0" />
      <mass
        value="0.0230007365895397" />
      <inertia
        ixx="3.38038527155296E-06"
        ixy="2.66636683878931E-09"
        ixz="-8.41838748723415E-11"
        iyy="1.0750315407539E-06"
        iyz="-1.37683480362091E-09"
        izz="2.85194124414614E-06" />
    </inertial>
    <visual>
      <origin
        xyz="0 0 0"
        rpy="0 0 0" />
      <geometry>
        <mesh
          filename="../meshes/Hip_L.STL" />
      </geometry>
      <material
        name="">
        <color
          rgba="0.792156862745098 0.819607843137255 0.933333333333333 1" />
      </material>
    </visual>
    <collision>
      <origin
        xyz="0 0 0"
        rpy="0 0 0" />
      <geometry>
        <mesh
          filename="../meshes/Hip_L.STL" />
      </geometry>
    </collision>
  </link>
  <joint
    name="Hip_L"
    type="revolute">
    <origin
      xyz="0.0500000000000003 -0.0581271117592202 0.000499999999998217"
      rpy="0 0 0" />
    <parent
      link="Body" />
    <child
      link="Hip_L" />
    <axis
      xyz="0 0 1" />
    <limit
      lower="-1.57"
      upper="1.57"
      effort="0.52"
      velocity="10.89" />
  </joint>
  <link
    name="Knee_L">
    <inertial>
      <origin
        xyz="-0.000264092013899347 -0.0224188787501997 9.42397503331113E-06"
        rpy="0 0 0" />
      <mass
        value="0.022604308352287" />
      <inertia
        ixx="3.27436167088692E-06"
        ixy="2.66811008457903E-09"
        ixz="-8.29162619234519E-11"
        iyy="1.11333471633781E-06"
        iyz="-1.37858113387165E-09"
        izz="2.83878279589868E-06" />
    </inertial>
    <visual>
      <origin
        xyz="0 0 0"
        rpy="0 0 0" />
      <geometry>
        <mesh
          filename="../meshes/Knee_L.STL" />
      </geometry>
      <material
        name="">
        <color
          rgba="0.792156862745098 0.819607843137255 0.933333333333333 1" />
      </material>
    </visual>
    <collision>
      <origin
        xyz="0 0 0"
        rpy="0 0 0" />
      <geometry>
        <mesh
          filename="../meshes/Knee_L.STL" />
      </geometry>
    </collision>
  </link>
  <joint
    name="Knee_L"
    type="revolute">
    <origin
      xyz="0.000500000000000216 -0.0473161341528267 -0.000500000000000007"
      rpy="0 0 0" />
    <parent
      link="Hip_L" />
    <child
      link="Knee_L" />
    <axis
      xyz="1 0 0" />
    <limit
      lower="-1.57"
      upper="1.57"
      effort="0.52"
      velocity="10.89" />
  </joint>
  <link
    name="Ankle_L">
    <inertial>
      <origin
        xyz="-0.000458850309986318 -0.0204363823905409 -1.04380806352678E-11"
        rpy="0 0 0" />
      <mass
        value="0.0318831730757301" />
      <inertia
        ixx="3.0992605738912E-06"
        ixy="1.74478800581368E-12"
        ixz="8.62441033791981E-14"
        iyy="5.54844222417291E-06"
        iyz="-1.54222971828772E-15"
        izz="5.68034830110216E-06" />
    </inertial>
    <visual>
      <origin
        xyz="0 0 0"
        rpy="0 0 0" />
      <geometry>
        <mesh
          filename="../meshes/Ankle_L.STL" />
      </geometry>
      <material
        name="">
        <color
          rgba="0.792156862745098 0.819607843137255 0.933333333333333 1" />
      </material>
    </visual>
    <collision>
      <origin
        xyz="0 0 0"
        rpy="0 0 0" />
      <geometry>
        <mesh
          filename="../meshes/Ankle_L.STL" />
      </geometry>
    </collision>
  </link>
  <joint
    name="Ankle_L"
    type="revolute">
    <origin
      xyz="0 -0.0473161341528267 0"
      rpy="0 0 0" />
    <parent
      link="Knee_L" />
    <child
      link="Ankle_L" />
    <axis
      xyz="1 0 0" />
    <limit
      lower="-1.57"
      upper="1.57"
      effort="0.52"
      velocity="10.89" />
  </joint>
</robot>