<?xml version="1.0" encoding="utf-8"?>
<!-- This URDF was automatically created by SolidWorks to URDF Exporter! Originally created by Stephen Brawner (brawner@gmail.com) 
     Commit Version: 1.6.0-4-g7f85cfe  Build Version: 1.6.7995.38578
     For more information, please see http://wiki.ros.org/sw_urdf_exporter -->
<robot
  name="WalkBot4Leg_Long">
  <link
    name="Body">
    <inertial>
      <origin
        xyz="8.17357455831703E-06 -8.19433772981432E-07 -0.00300170877774879"
        rpy="0 0 0" />
      <mass
        value="0.50" />
      <inertia
        ixx="0.0013074898058424"
        ixy="3.36188956883991E-10"
        ixz="1.60521989431855E-07"
        iyy="0.00339179073259683"
        iyz="5.51431836645588E-09"
        izz="0.00441758469225806" />
    </inertial>
    <visual>
      <origin
        xyz="0 0 0"
        rpy="0 0 0" />
      <geometry>
        <mesh
          filename="../meshes/Body.STL" />
      </geometry>
      <material
        name="">
        <color
          rgba="0.792156862745098 0.819607843137255 0.933333333333333 1" />
      </material>
    </visual>
    <collision>
      <origin
        xyz="0 0 0"
        rpy="0 0 0" />
      <geometry>
        <mesh
          filename="../meshes/Body.STL" />
      </geometry>
    </collision>
  </link>
  <link
    name="FR1_Servo">
    <inertial>
      <origin
        xyz="6.63024617987423E-05 0.00017480111947784 -0.0318010030269155"
        rpy="0 0 0" />
      <mass
        value="0.0230007365895397" />
      <inertia
        ixx="2.85194124414614E-06"
        ixy="-8.41838748723463E-11"
        ixz="-1.37683480361865E-09"
        iyy="3.38038527155297E-06"
        iyz="2.66636683877571E-09"
        izz="1.0750315407539E-06" />
    </inertial>
    <visual>
      <origin
        xyz="0 0 0"
        rpy="0 0 0" />
      <geometry>
        <mesh
          filename="../meshes/FR1_Servo.STL" />
      </geometry>
      <material
        name="">
        <color
          rgba="1 1 1 1" />
      </material>
    </visual>
    <collision>
      <origin
        xyz="0 0 0"
        rpy="0 0 0" />
      <geometry>
        <mesh
          filename="../meshes/FR1_Servo.STL" />
      </geometry>
    </collision>
  </link>
  <joint
    name="FR1"
    type="revolute">
    <origin
      xyz="0.071 -0.05 -0.0488561341528267"
      rpy="0 0 0" />
    <parent
      link="Body" />
    <child
      link="FR1_Servo" />
    <axis
      xyz="1 0 0" />
    <limit
      lower="-1.5708"
      upper="1.5708"
      effort="0.52"
      velocity="10.89" />
  </joint>
  <link
    name="FR2_Servo">
    <inertial>
      <origin
        xyz="9.14719030635502E-06 0.000228979303958821 -0.044087748012233"
        rpy="0 0 0" />
      <mass
        value="0.0232882918603983" />
      <inertia
        ixx="3.65596349321669E-06"
        ixy="-8.28434828683659E-11"
        ixz="-1.37858113387024E-09"
        iyy="4.08685344603095E-06"
        iyz="2.66811008456549E-09"
        izz="1.12460835432337E-06" />
    </inertial>
    <visual>
      <origin
        xyz="0 0 0"
        rpy="0 0 0" />
      <geometry>
        <mesh
          filename="../meshes/FR2_Servo.STL" />
      </geometry>
      <material
        name="">
        <color
          rgba="1 1 1 1" />
      </material>
    </visual>
    <collision>
      <origin
        xyz="0 0 0"
        rpy="0 0 0" />
      <geometry>
        <mesh
          filename="../meshes/FR2_Servo.STL" />
      </geometry>
    </collision>
  </link>
  <joint
    name="FR2"
    type="revolute">
    <origin
      xyz="0 0 -0.0474161341528266"
      rpy="0 0 0" />
    <parent
      link="FR1_Servo" />
    <child
      link="FR2_Servo" />
    <axis
      xyz="0 -1 0" />
    <limit
      lower="-1.5708"
      upper="1.5708"
      effort="0.52"
      velocity="10.89" />
  </joint>
  <link
    name="FR3_Servo">
    <inertial>
      <origin
        xyz="2.69406019715035E-09 7.81684544896785E-05 -0.0359209968856328"
        rpy="0 0 0" />
      <mass
        value="0.0167842210685734" />
      <inertia
        ixx="2.29107229796221E-06"
        ixy="1.40834939749781E-13"
        ixz="-1.41793132434197E-13"
        iyy="2.61195222976322E-06"
        iyz="1.24376477992814E-12"
        izz="1.24659676057817E-06" />
    </inertial>
    <visual>
      <origin
        xyz="0 0 0"
        rpy="0 0 0" />
      <geometry>
        <mesh
          filename="../meshes/FR3_Servo.STL" />
      </geometry>
      <material
        name="">
        <color
          rgba="1 1 1 1" />
      </material>
    </visual>
    <collision>
      <origin
        xyz="0 0 0"
        rpy="0 0 0" />
      <geometry>
        <mesh
          filename="../meshes/FR3_Servo.STL" />
      </geometry>
    </collision>
  </link>
  <joint
    name="FR3"
    type="revolute">
    <origin
      xyz="0 0 -0.0624161341528267"
      rpy="0 0 0" />
    <parent
      link="FR2_Servo" />
    <child
      link="FR3_Servo" />
    <axis
      xyz="0 -1 0" />
    <limit
      lower="-1.5708"
      upper="1.5708"
      effort="0.52"
      velocity="10.89" />
  </joint>
  <link
    name="FL1_Servo">
    <inertial>
      <origin
        xyz="6.63024617987562E-05 0.000174801119477853 -0.0318010030269155"
        rpy="0 0 0" />
      <mass
        value="0.0230007365895397" />
      <inertia
        ixx="2.85194124414614E-06"
        ixy="-8.41838748722794E-11"
        ixz="-1.37683480361837E-09"
        iyy="3.38038527155296E-06"
        iyz="2.66636683877604E-09"
        izz="1.0750315407539E-06" />
    </inertial>
    <visual>
      <origin
        xyz="0 0 0"
        rpy="0 0 0" />
      <geometry>
        <mesh
          filename="../meshes/FL1_Servo.STL" />
      </geometry>
      <material
        name="">
        <color
          rgba="0.792156862745098 0.819607843137255 0.933333333333333 1" />
      </material>
    </visual>
    <collision>
      <origin
        xyz="0 0 0"
        rpy="0 0 0" />
      <geometry>
        <mesh
          filename="../meshes/FL1_Servo.STL" />
      </geometry>
    </collision>
  </link>
  <joint
    name="FL1"
    type="revolute">
    <origin
      xyz="0.071 0.05 -0.0488561341528267"
      rpy="0 0 0" />
    <parent
      link="Body" />
    <child
      link="FL1_Servo" />
    <axis
      xyz="1 0 0" />
    <limit
      lower="-1.5708"
      upper="1.5708"
      effort="0.52"
      velocity="10.89" />
  </joint>
  <link
    name="FL2_Servo">
    <inertial>
      <origin
        xyz="9.14719030635502E-06 0.0002289793039588 -0.044087748012233"
        rpy="0 0 0" />
      <mass
        value="0.0232882918603984" />
      <inertia
        ixx="3.65596349321669E-06"
        ixy="-8.28434828684451E-11"
        ixz="-1.37858113387041E-09"
        iyy="4.08685344603095E-06"
        iyz="2.66811008456588E-09"
        izz="1.12460835432337E-06" />
    </inertial>
    <visual>
      <origin
        xyz="0 0 0"
        rpy="0 0 0" />
      <geometry>
        <mesh
          filename="../meshes/FL2_Servo.STL" />
      </geometry>
      <material
        name="">
        <color
          rgba="1 1 1 1" />
      </material>
    </visual>
    <collision>
      <origin
        xyz="0 0 0"
        rpy="0 0 0" />
      <geometry>
        <mesh
          filename="../meshes/FL2_Servo.STL" />
      </geometry>
    </collision>
  </link>
  <joint
    name="FL2"
    type="revolute">
    <origin
      xyz="0 0 -0.0474161341528266"
      rpy="0 0 0" />
    <parent
      link="FL1_Servo" />
    <child
      link="FL2_Servo" />
    <axis
      xyz="0 -1 0" />
    <limit
      lower="-1.5708"
      upper="1.5708"
      effort="0.52"
      velocity="10.89" />
  </joint>
  <link
    name="FL3_Servo">
    <inertial>
      <origin
        xyz="2.69406022490593E-09 7.81684544896993E-05 -0.0359209968856328"
        rpy="0 0 0" />
      <mass
        value="0.0167842210685734" />
      <inertia
        ixx="2.29107229796221E-06"
        ixy="1.40834939384918E-13"
        ixz="-1.41793131343822E-13"
        iyy="2.61195222976322E-06"
        iyz="1.24376477811362E-12"
        izz="1.24659676057817E-06" />
    </inertial>
    <visual>
      <origin
        xyz="0 0 0"
        rpy="0 0 0" />
      <geometry>
        <mesh
          filename="../meshes/FL3_Servo.STL" />
      </geometry>
      <material
        name="">
        <color
          rgba="0.792156862745098 0.819607843137255 0.933333333333333 1" />
      </material>
    </visual>
    <collision>
      <origin
        xyz="0 0 0"
        rpy="0 0 0" />
      <geometry>
        <mesh
          filename="../meshes/FL3_Servo.STL" />
      </geometry>
    </collision>
  </link>
  <joint
    name="FL3"
    type="revolute">
    <origin
      xyz="0 0 -0.0624161341528267"
      rpy="0 0 0" />
    <parent
      link="FL2_Servo" />
    <child
      link="FL3_Servo" />
    <axis
      xyz="0 -1 0" />
    <limit
      lower="-1.5708"
      upper="1.5708"
      effort="0.52"
      velocity="10.89" />
  </joint>
  <link
    name="BR1_Servo">
    <inertial>
      <origin
        xyz="6.63024617987423E-05 0.000174801119477819 -0.0318010030269155"
        rpy="0 0 0" />
      <mass
        value="0.0230007365895397" />
      <inertia
        ixx="2.85194124414614E-06"
        ixy="-8.41838748724021E-11"
        ixz="-1.37683480361916E-09"
        iyy="3.38038527155296E-06"
        iyz="2.66636683877556E-09"
        izz="1.0750315407539E-06" />
    </inertial>
    <visual>
      <origin
        xyz="0 0 0"
        rpy="0 0 0" />
      <geometry>
        <mesh
          filename="../meshes/BR1_Servo.STL" />
      </geometry>
      <material
        name="">
        <color
          rgba="1 1 1 1" />
      </material>
    </visual>
    <collision>
      <origin
        xyz="0 0 0"
        rpy="0 0 0" />
      <geometry>
        <mesh
          filename="../meshes/BR1_Servo.STL" />
      </geometry>
    </collision>
  </link>
  <joint
    name="BR1"
    type="revolute">
    <origin
      xyz="-0.071 -0.05 -0.0488561341528267"
      rpy="0 0 0" />
    <parent
      link="Body" />
    <child
      link="BR1_Servo" />
    <axis
      xyz="1 0 0" />
    <limit
      lower="-1.5708"
      upper="1.5708"
      effort="0.52"
      velocity="10.89" />
  </joint>
  <link
    name="BR2_Servo">
    <inertial>
      <origin
        xyz="9.14719030641054E-06 0.000228979303958814 -0.0440877480122329"
        rpy="0 0 0" />
      <mass
        value="0.0232882918603984" />
      <inertia
        ixx="3.65596349321669E-06"
        ixy="-8.28434828684524E-11"
        ixz="-1.37858113386765E-09"
        iyy="4.08685344603095E-06"
        iyz="2.66811008456746E-09"
        izz="1.12460835432337E-06" />
    </inertial>
    <visual>
      <origin
        xyz="0 0 0"
        rpy="0 0 0" />
      <geometry>
        <mesh
          filename="../meshes/BR2_Servo.STL" />
      </geometry>
      <material
        name="">
        <color
          rgba="0.792156862745098 0.819607843137255 0.933333333333333 1" />
      </material>
    </visual>
    <collision>
      <origin
        xyz="0 0 0"
        rpy="0 0 0" />
      <geometry>
        <mesh
          filename="../meshes/BR2_Servo.STL" />
      </geometry>
    </collision>
  </link>
  <joint
    name="BR2"
    type="revolute">
    <origin
      xyz="0 0 -0.0474161341528266"
      rpy="0 0 0" />
    <parent
      link="BR1_Servo" />
    <child
      link="BR2_Servo" />
    <axis
      xyz="0 -1 0" />
    <limit
      lower="-1.5708"
      upper="1.5708"
      effort="0.52"
      velocity="10.89" />
  </joint>
  <link
    name="BR3_Servo">
    <inertial>
      <origin
        xyz="2.69406021102814E-09 7.81684544896924E-05 -0.0359209968856328"
        rpy="0 0 0" />
      <mass
        value="0.0167842210685734" />
      <inertia
        ixx="2.29107229796221E-06"
        ixy="1.40834939459237E-13"
        ixz="-1.41793130548659E-13"
        iyy="2.61195222976322E-06"
        iyz="1.24376478015691E-12"
        izz="1.24659676057817E-06" />
    </inertial>
    <visual>
      <origin
        xyz="0 0 0"
        rpy="0 0 0" />
      <geometry>
        <mesh
          filename="../meshes/BR3_Servo.STL" />
      </geometry>
      <material
        name="">
        <color
          rgba="1 1 1 1" />
      </material>
    </visual>
    <collision>
      <origin
        xyz="0 0 0"
        rpy="0 0 0" />
      <geometry>
        <mesh
          filename="../meshes/BR3_Servo.STL" />
      </geometry>
    </collision>
  </link>
  <joint
    name="BR3"
    type="revolute">
    <origin
      xyz="0 0 -0.0624161341528267"
      rpy="0 0 0" />
    <parent
      link="BR2_Servo" />
    <child
      link="BR3_Servo" />
    <axis
      xyz="0 -1 0" />
    <limit
      lower="-1.5708"
      upper="1.5708"
      effort="0.52"
      velocity="10.89" />
  </joint>
  <link
    name="BL1_Servo">
    <inertial>
      <origin
        xyz="6.63024617987562E-05 0.000174801119477846 -0.0318010030269155"
        rpy="0 0 0" />
      <mass
        value="0.0230007365895397" />
      <inertia
        ixx="2.85194124414614E-06"
        ixy="-8.4183874872215E-11"
        ixz="-1.37683480361878E-09"
        iyy="3.38038527155297E-06"
        iyz="2.66636683877589E-09"
        izz="1.0750315407539E-06" />
    </inertial>
    <visual>
      <origin
        xyz="0 0 0"
        rpy="0 0 0" />
      <geometry>
        <mesh
          filename="../meshes/BL1_Servo.STL" />
      </geometry>
      <material
        name="">
        <color
          rgba="1 1 1 1" />
      </material>
    </visual>
    <collision>
      <origin
        xyz="0 0 0"
        rpy="0 0 0" />
      <geometry>
        <mesh
          filename="../meshes/BL1_Servo.STL" />
      </geometry>
    </collision>
  </link>
  <joint
    name="BL1"
    type="revolute">
    <origin
      xyz="-0.071 0.05 -0.0488561341528267"
      rpy="0 0 0" />
    <parent
      link="Body" />
    <child
      link="BL1_Servo" />
    <axis
      xyz="1 0 0" />
    <limit
      lower="-1.5708"
      upper="1.5708"
      effort="0.52"
      velocity="10.89" />
  </joint>
  <link
    name="BL2_Servo">
    <inertial>
      <origin
        xyz="9.14719030642441E-06 0.000228979303958821 -0.0440877480122329"
        rpy="0 0 0" />
      <mass
        value="0.0232882918603984" />
      <inertia
        ixx="3.65596349321669E-06"
        ixy="-8.28434828685134E-11"
        ixz="-1.37858113386725E-09"
        iyy="4.08685344603095E-06"
        iyz="2.66811008456588E-09"
        izz="1.12460835432337E-06" />
    </inertial>
    <visual>
      <origin
        xyz="0 0 0"
        rpy="0 0 0" />
      <geometry>
        <mesh
          filename="../meshes/BL2_Servo.STL" />
      </geometry>
      <material
        name="">
        <color
          rgba="1 1 1 1" />
      </material>
    </visual>
    <collision>
      <origin
        xyz="0 0 0"
        rpy="0 0 0" />
      <geometry>
        <mesh
          filename="../meshes/BL2_Servo.STL" />
      </geometry>
    </collision>
  </link>
  <joint
    name="BL2"
    type="revolute">
    <origin
      xyz="0 0 -0.0474161341528266"
      rpy="0 0 0" />
    <parent
      link="BL1_Servo" />
    <child
      link="BL2_Servo" />
    <axis
      xyz="0 -1 0" />
    <limit
      lower="-1.5708"
      upper="1.5708"
      effort="0.52"
      velocity="10.89" />
  </joint>
  <link
    name="BL3_Servo">
    <inertial>
      <origin
        xyz="2.6941E-09 7.8168E-05 -0.035921"
        rpy="0 0 0" />
      <mass
        value="0.016784" />
      <inertia
        ixx="2.2911E-06"
        ixy="1.4083E-13"
        ixz="-1.4179E-13"
        iyy="2.612E-06"
        iyz="1.2438E-12"
        izz="1.2466E-06" />
    </inertial>
    <visual>
      <origin
        xyz="0 0 0"
        rpy="0 0 0" />
      <geometry>
        <mesh
          filename="../meshes/BL3_Servo.STL" />
      </geometry>
      <material
        name="">
        <color
          rgba="1 1 1 1" />
      </material>
    </visual>
    <collision>
      <origin
        xyz="0 0 0"
        rpy="0 0 0" />
      <geometry>
        <mesh
          filename="../meshes/BL3_Servo.STL" />
      </geometry>
    </collision>
  </link>
  <joint
    name="BL3"
    type="revolute">
    <origin
      xyz="0 0 -0.062416"
      rpy="0 0 0" />
    <parent
      link="BL2_Servo" />
    <child
      link="BL3_Servo" />
    <axis
      xyz="0 -1 0" />
    <limit
      lower="-1.5708"
      upper="1.5708"
      effort="0.52"
      velocity="10.89" />
  </joint>
</robot>