<?xml version="1.0" encoding="utf-8"?>
<!-- This URDF was automatically created by SolidWorks to URDF Exporter! Originally created by Stephen Brawner (brawner@gmail.com) 
     Commit Version: 1.6.0-4-g7f85cfe  Build Version: 1.6.7995.38578
     For more information, please see http://wiki.ros.org/sw_urdf_exporter -->
<robot
  name="WalkBot">
  <link
    name="Body">
    <inertial>
      <origin
        xyz="8.8269E-07 -8.2073E-07 -0.0028082"
        rpy="0 0 0" />
      <mass
        value="0.51911" />
      <inertia
        ixx="0.00065337"
        ixy="1.6809E-10"
        ixz="1.5544E-07"
        iyy="0.00046997"
        iyz="2.7572E-09"
        izz="0.00098313" />
    </inertial>
    <visual>
      <origin
        xyz="0 0 0"
        rpy="0 0 0" />
      <geometry>
        <mesh
          filename="package://WalkBot/meshes/Body.STL" />
      </geometry>
      <material
        name="">
        <color
          rgba="0.79216 0.81961 0.93333 1" />
      </material>
    </visual>
    <collision>
      <origin
        xyz="0 0 0"
        rpy="0 0 0" />
      <geometry>
        <mesh
          filename="package://WalkBot/meshes/Body.STL" />
      </geometry>
    </collision>
  </link>
  <link
    name="Servo1_Left">
    <inertial>
      <origin
        xyz="6.6302E-05 0.0001748 -0.031801"
        rpy="0 0 0" />
      <mass
        value="0.023001" />
      <inertia
        ixx="2.8519E-06"
        ixy="-8.4184E-11"
        ixz="-1.3768E-09"
        iyy="3.3804E-06"
        iyz="2.6664E-09"
        izz="1.075E-06" />
    </inertial>
    <visual>
      <origin
        xyz="0 0 0"
        rpy="0 0 0" />
      <geometry>
        <mesh
          filename="package://WalkBot/meshes/Servo1_Left.STL" />
      </geometry>
      <material
        name="">
        <color
          rgba="0.79216 0.81961 0.93333 1" />
      </material>
    </visual>
    <collision>
      <origin
        xyz="0 0 0"
        rpy="0 0 0" />
      <geometry>
        <mesh
          filename="package://WalkBot/meshes/Servo1_Left.STL" />
      </geometry>
    </collision>
  </link>
  <joint
    name="hip_L"
    type="revolute">
    <origin
      xyz="0 0.05 -0.048627"
      rpy="0 0 0" />
    <parent
      link="Body" />
    <child
      link="Servo1_Left" />
    <axis
      xyz="1 0 0" />
    <limit
      lower="-1.5708"
      upper="1.5708"
      effort="0.52"
      velocity="10.89" />
  </joint>
  <link
    name="Servo2_Left">
    <inertial>
      <origin
        xyz="9.424E-06 0.00023591 -0.031996"
        rpy="0 0 0" />
      <mass
        value="0.022604" />
      <inertia
        ixx="2.8388E-06"
        ixy="-8.2916E-11"
        ixz="-1.3786E-09"
        iyy="3.2744E-06"
        iyz="2.6681E-09"
        izz="1.1133E-06" />
    </inertial>
    <visual>
      <origin
        xyz="0 0 0"
        rpy="0 0 0" />
      <geometry>
        <mesh
          filename="package://WalkBot/meshes/Servo2_Left.STL" />
      </geometry>
      <material
        name="">
        <color
          rgba="0.79216 0.81961 0.93333 1" />
      </material>
    </visual>
    <collision>
      <origin
        xyz="0 0 0"
        rpy="0 0 0" />
      <geometry>
        <mesh
          filename="package://WalkBot/meshes/Servo2_Left.STL" />
      </geometry>
    </collision>
  </link>
  <joint
    name="knee_L"
    type="revolute">
    <origin
      xyz="0 0 -0.047416"
      rpy="0 0 0" />
    <parent
      link="Servo1_Left" />
    <child
      link="Servo2_Left" />
    <axis
      xyz="0 1 0" />
    <limit
      lower="-1.5708"
      upper="1.5708"
      effort="0.52"
      velocity="10.89" />
  </joint>
  <link
    name="Servo3_Left">
    <inertial>
      <origin
        xyz="2.8085E-09 8.1489E-05 -0.024657"
        rpy="0 0 0" />
      <mass
        value="0.0161" />
      <inertia
        ixx="1.4739E-06"
        ixy="6.8056E-14"
        ixz="-1.4179E-13"
        iyy="1.7995E-06"
        iyz="1.2438E-12"
        izz="1.2353E-06" />
    </inertial>
    <visual>
      <origin
        xyz="0 0 0"
        rpy="0 0 0" />
      <geometry>
        <mesh
          filename="package://WalkBot/meshes/Servo3_Left.STL" />
      </geometry>
      <material
        name="">
        <color
          rgba="0.79216 0.81961 0.93333 1" />
      </material>
    </visual>
    <collision>
      <origin
        xyz="0 0 0"
        rpy="0 0 0" />
      <geometry>
        <mesh
          filename="package://WalkBot/meshes/Servo3_Left.STL" />
      </geometry>
    </collision>
  </link>
  <joint
    name="ankle_L"
    type="revolute">
    <origin
      xyz="0 0 -0.047416"
      rpy="0 0 0" />
    <parent
      link="Servo2_Left" />
    <child
      link="Servo3_Left" />
    <axis
      xyz="0 1 0" />
    <limit
      lower="-1.5708"
      upper="1.5708"
      effort="0.52"
      velocity="10.89" />
  </joint>
  <link
    name="Servo1_Right">
    <inertial>
      <origin
        xyz="6.6302E-05 0.0001748 -0.031801"
        rpy="0 0 0" />
      <mass
        value="0.023001" />
      <inertia
        ixx="2.8519E-06"
        ixy="-8.4184E-11"
        ixz="-1.3768E-09"
        iyy="3.3804E-06"
        iyz="2.6664E-09"
        izz="1.075E-06" />
    </inertial>
    <visual>
      <origin
        xyz="0 0 0"
        rpy="0 0 0" />
      <geometry>
        <mesh
          filename="package://WalkBot/meshes/Servo1_Right.STL" />
      </geometry>
      <material
        name="">
        <color
          rgba="0.79216 0.81961 0.93333 1" />
      </material>
    </visual>
    <collision>
      <origin
        xyz="0 0 0"
        rpy="0 0 0" />
      <geometry>
        <mesh
          filename="package://WalkBot/meshes/Servo1_Right.STL" />
      </geometry>
    </collision>
  </link>
  <joint
    name="hip_R"
    type="revolute">
    <origin
      xyz="0 -0.05 -0.048627"
      rpy="0 0 0" />
    <parent
      link="Body" />
    <child
      link="Servo1_Right" />
    <axis
      xyz="1 0 0" />
    <limit
      lower="-1.5708"
      upper="1.5708"
      effort="0.52"
      velocity="10.89" />
  </joint>
  <link
    name="Servo2_Right">
    <inertial>
      <origin
        xyz="9.424E-06 0.00023591 -0.031996"
        rpy="0 0 0" />
      <mass
        value="0.022604" />
      <inertia
        ixx="2.8388E-06"
        ixy="-8.2916E-11"
        ixz="-1.3786E-09"
        iyy="3.2744E-06"
        iyz="2.6681E-09"
        izz="1.1133E-06" />
    </inertial>
    <visual>
      <origin
        xyz="0 0 0"
        rpy="0 0 0" />
      <geometry>
        <mesh
          filename="package://WalkBot/meshes/Servo2_Right.STL" />
      </geometry>
      <material
        name="">
        <color
          rgba="0.79216 0.81961 0.93333 1" />
      </material>
    </visual>
    <collision>
      <origin
        xyz="0 0 0"
        rpy="0 0 0" />
      <geometry>
        <mesh
          filename="package://WalkBot/meshes/Servo2_Right.STL" />
      </geometry>
    </collision>
  </link>
  <joint
    name="knee_R"
    type="revolute">
    <origin
      xyz="0 0 -0.047416"
      rpy="0 0 0" />
    <parent
      link="Servo1_Right" />
    <child
      link="Servo2_Right" />
    <axis
      xyz="0 1 0" />
    <limit
      lower="-1.5708"
      upper="1.5708"
      effort="0.52"
      velocity="10.89" />
  </joint>
  <link
    name="Servo3_Right">
    <inertial>
      <origin
        xyz="2.8085E-09 8.1489E-05 -0.024657"
        rpy="0 0 0" />
      <mass
        value="0.0161" />
      <inertia
        ixx="1.4739E-06"
        ixy="6.8056E-14"
        ixz="-1.4179E-13"
        iyy="1.7995E-06"
        iyz="1.2438E-12"
        izz="1.2353E-06" />
    </inertial>
    <visual>
      <origin
        xyz="0 0 0"
        rpy="0 0 0" />
      <geometry>
        <mesh
          filename="package://WalkBot/meshes/Servo3_Right.STL" />
      </geometry>
      <material
        name="">
        <color
          rgba="0.79216 0.81961 0.93333 1" />
      </material>
    </visual>
    <collision>
      <origin
        xyz="0 0 0"
        rpy="0 0 0" />
      <geometry>
        <mesh
          filename="package://WalkBot/meshes/Servo3_Right.STL" />
      </geometry>
    </collision>
  </link>
  <joint
    name="ankle_R"
    type="revolute">
    <origin
      xyz="0 0 -0.047416"
      rpy="0 0 0" />
    <parent
      link="Servo2_Right" />
    <child
      link="Servo3_Right" />
    <axis
      xyz="0 1 0" />
    <limit
      lower="-1.5708"
      upper="1.5708"
      effort="0.52"
      velocity="10.89" />
  </joint>
</robot>