<?xml version="1.0" encoding="utf-8"?>
<!-- This URDF was automatically created by SolidWorks to URDF Exporter! Originally created by Stephen Brawner (brawner@gmail.com) 
     Commit Version: 1.6.0-4-g7f85cfe  Build Version: 1.6.7995.38578
     For more information, please see http://wiki.ros.org/sw_urdf_exporter -->
<robot
  name="WalkBot">
  <link
    name="body">
    <inertial>
      <origin
        xyz="-9.66925606769864E-07 -0.00329829865280169 1.82495832519378E-05"
        rpy="0 0 0" />
      <mass
        value="0.440618738122415" />
      <inertia
        ixx="0.000393480475203283"
        ixy="2.75715918325615E-09"
        ixz="1.68095672530006E-10"
        iyy="0.000672030111990303"
        iyz="5.33273059311417E-09"
        izz="0.000397942731290007" />
    </inertial>
    <visual>
      <origin
        xyz="0 0 0"
        rpy="0 0 0" />
      <geometry>
        <mesh
          filename="../meshes/body.STL" />
      </geometry>
      <material
        name="">
        <color
          rgba="0.792156862745098 0.819607843137255 0.933333333333333 1" />
      </material>
    </visual>
    <collision>
      <origin
        xyz="0 0 0"
        rpy="0 0 0" />
      <geometry>
        <mesh
          filename="../meshes/body.STL" />
      </geometry>
    </collision>
  </link>
  <link
    name="servo1r">
    <inertial>
      <origin
        xyz="2.9811117204518E-05 -0.0346910121894035 -0.000509969127238129"
        rpy="0 0 0" />
      <mass
        value="0.0213682467147692" />
      <inertia
        ixx="3.25958248565221E-06"
        ixy="-2.66636529654879E-09"
        ixz="-8.41577076328632E-11"
        iyy="1.04298724915849E-06"
        iyz="1.37857959164E-09"
        izz="2.70162820946051E-06" />
    </inertial>
    <visual>
      <origin
        xyz="0 0 0"
        rpy="0 0 0" />
      <geometry>
        <mesh
          filename="../meshes/servo1r.STL" />
      </geometry>
      <material
        name="">
        <color
          rgba="0.792156862745098 0.819607843137255 0.933333333333333 1" />
      </material>
    </visual>
    <collision>
      <origin
        xyz="0 0 0"
        rpy="0 0 0" />
      <geometry>
        <mesh
          filename="../meshes/servo1r.STL" />
      </geometry>
    </collision>
  </link>
  <joint
    name="hipr"
    type="revolute">
    <origin
      xyz="0.04 -0.048627 0.0003"
      rpy="0 0 0" />
    <parent
      link="body" />
    <child
      link="servo1r" />
    <axis
      xyz="0 0 -1" />
    <limit
      lower="-1.5708"
      upper="1.5708"
      effort="0.22"
      velocity="38" />
  </joint>
  <link
    name="servo2r">
    <inertial>
      <origin
        xyz="0.000308287765976077 -0.0349560457002559 -0.000227414690784307"
        rpy="0 0 0" />
      <mass
        value="0.0209718184775165" />
      <inertia
        ixx="3.14944361251738E-06"
        ixy="-2.66636529654835E-09"
        ixz="-8.28909281611623E-11"
        iyy="1.08188083399424E-06"
        iyz="1.37857959164006E-09"
        izz="2.6855511067329E-06" />
    </inertial>
    <visual>
      <origin
        xyz="0 0 0"
        rpy="0 0 0" />
      <geometry>
        <mesh
          filename="../meshes/servo2r.STL" />
      </geometry>
      <material
        name="">
        <color
          rgba="0.792156862745098 0.819607843137255 0.933333333333333 1" />
      </material>
    </visual>
    <collision>
      <origin
        xyz="0 0 0"
        rpy="0 0 0" />
      <geometry>
        <mesh
          filename="../meshes/servo2r.STL" />
      </geometry>
    </collision>
  </link>
  <joint
    name="kneer"
    type="revolute">
    <origin
      xyz="-0.0002445 -0.047416 -0.0005"
      rpy="0 0 0" />
    <parent
      link="servo1r" />
    <child
      link="servo2r" />
    <axis
      xyz="1 0 0" />
    <limit
      lower="-1.5708"
      upper="1.5708"
      effort="0.22"
      velocity="38" />
    <mimic
      joint="hipr"
      multiplier="1"
      offset="0" />
  </joint>
  <link
    name="servo3r">
    <inertial>
      <origin
        xyz="0.000499999999999961 -0.0320629887870761 -0.000283443855796324"
        rpy="0 0 0" />
      <mass
        value="0.0309227624152866" />
      <inertia
        ixx="3.11278543548184E-06"
        ixy="2.09773003343448E-21"
        ixz="4.95387982517753E-14"
        iyy="5.79440254144382E-06"
        iyz="-8.83367243149169E-22"
        izz="5.81487246004715E-06" />
    </inertial>
    <visual>
      <origin
        xyz="0 0 0"
        rpy="0 0 0" />
      <geometry>
        <mesh
          filename="../meshes/servo3r.STL" />
      </geometry>
      <material
        name="">
        <color
          rgba="0.792156862745098 0.819607843137255 0.933333333333333 1" />
      </material>
    </visual>
    <collision>
      <origin
        xyz="0 0 0"
        rpy="0 0 0" />
      <geometry>
        <mesh
          filename="../meshes/servo3r.STL" />
      </geometry>
    </collision>
  </link>
  <joint
    name="ankler"
    type="revolute">
    <origin
      xyz="0 -0.047416 -0.0002555"
      rpy="0 0 0" />
    <parent
      link="servo2r" />
    <child
      link="servo3r" />
    <axis
      xyz="1 0 0" />
    <limit
      lower="-1.5708"
      upper="1.5708"
      effort="0.22"
      velocity="38" />
    <mimic
      joint="hipr"
      multiplier="1"
      offset="0" />
  </joint>
  <link
    name="servo1l">
    <inertial>
      <origin
        xyz="2.9811117204584E-05 -0.0346910121894035 -0.000509969127238129"
        rpy="0 0 0" />
      <mass
        value="0.0213682467147692" />
      <inertia
        ixx="3.25958248565221E-06"
        ixy="-2.66636529654381E-09"
        ixz="-8.41577076327869E-11"
        iyy="1.04298724915849E-06"
        iyz="1.37857959163981E-09"
        izz="2.70162820946052E-06" />
    </inertial>
    <visual>
      <origin
        xyz="0 0 0"
        rpy="0 0 0" />
      <geometry>
        <mesh
          filename="../meshes/servo1l.STL" />
      </geometry>
      <material
        name="">
        <color
          rgba="0.792156862745098 0.819607843137255 0.933333333333333 1" />
      </material>
    </visual>
    <collision>
      <origin
        xyz="0 0 0"
        rpy="0 0 0" />
      <geometry>
        <mesh
          filename="../meshes/servo1l.STL" />
      </geometry>
    </collision>
  </link>
  <joint
    name="hipl"
    type="revolute">
    <origin
      xyz="-0.04 -0.048627 0.0007"
      rpy="0 0 0" />
    <parent
      link="body" />
    <child
      link="servo1l" />
    <axis
      xyz="0 0 -1" />
    <limit
      lower="-1.5708"
      upper="1.5708"
      effort="0.22"
      velocity="38" />
    <mimic
      joint="hipr"
      multiplier="1"
      offset="0" />
  </joint>
  <link
    name="servo2l">
    <inertial>
      <origin
        xyz="0.000308287765976162 -0.0349560457002559 -0.000227414690784307"
        rpy="0 0 0" />
      <mass
        value="0.0209718184775166" />
      <inertia
        ixx="3.14944361251738E-06"
        ixy="-2.66636529654412E-09"
        ixz="-8.28909281612556E-11"
        iyy="1.08188083399424E-06"
        iyz="1.37857959163944E-09"
        izz="2.6855511067329E-06" />
    </inertial>
    <visual>
      <origin
        xyz="0 0 0"
        rpy="0 0 0" />
      <geometry>
        <mesh
          filename="../meshes/servo2l.STL" />
      </geometry>
      <material
        name="">
        <color
          rgba="0.792156862745098 0.819607843137255 0.933333333333333 1" />
      </material>
    </visual>
    <collision>
      <origin
        xyz="0 0 0"
        rpy="0 0 0" />
      <geometry>
        <mesh
          filename="../meshes/servo2l.STL" />
      </geometry>
    </collision>
  </link>
  <joint
    name="kneel"
    type="revolute">
    <origin
      xyz="-0.0002445 -0.047416 -0.0005"
      rpy="0 0 0" />
    <parent
      link="servo1l" />
    <child
      link="servo2l" />
    <axis
      xyz="1 0 0" />
    <limit
      lower="-1.5708"
      upper="1.5708"
      effort="0.22"
      velocity="38" />
    <mimic
      joint="hipr"
      multiplier="1"
      offset="0" />
  </joint>
  <link
    name="servo3l">
    <inertial>
      <origin
        xyz="0.000500000000000056 -0.0320629887870761 -0.000283443855796359"
        rpy="0 0 0" />
      <mass
        value="0.0309227624152866" />
      <inertia
        ixx="3.11278543548184E-06"
        ixy="-9.99234179964057E-22"
        ixz="4.95387955736643E-14"
        iyy="5.79440254144383E-06"
        iyz="-5.77069359544575E-23"
        izz="5.81487246004715E-06" />
    </inertial>
    <visual>
      <origin
        xyz="0 0 0"
        rpy="0 0 0" />
      <geometry>
        <mesh
          filename="../meshes/servo3l.STL" />
      </geometry>
      <material
        name="">
        <color
          rgba="0.792156862745098 0.819607843137255 0.933333333333333 1" />
      </material>
    </visual>
    <collision>
      <origin
        xyz="0 0 0"
        rpy="0 0 0" />
      <geometry>
        <mesh
          filename="../meshes/servo3l.STL" />
      </geometry>
    </collision>
  </link>
  <joint
    name="anklel"
    type="revolute">
    <origin
      xyz="0 -0.047416 -0.0002555"
      rpy="0 0 0" />
    <parent
      link="servo2l" />
    <child
      link="servo3l" />
    <axis
      xyz="1 0 0" />
    <limit
      lower="-1.5708"
      upper="1.5708"
      effort="0.22"
      velocity="38" />
    <mimic
      joint="hipr"
      multiplier="1"
      offset="0" />
  </joint>
</robot>