<?xml version="1.0" encoding="utf-8"?>
<!-- This URDF was automatically created by SolidWorks to URDF Exporter! Originally created by Stephen Brawner (brawner@gmail.com) 
     Commit Version: 1.6.0-4-g7f85cfe  Build Version: 1.6.7995.38578
     For more information, please see http://wiki.ros.org/sw_urdf_exporter -->
<robot
  name="WalkBot">
  <link
    name="Body">
    <inertial>
      <origin
        xyz="-8.1814E-07 -0.0027373 1.5441E-05"
        rpy="0 0 0" />
      <mass
        value="0.52075" />
      <inertia
        ixx="0.0004712"
        ixy="2.7572E-09"
        ixz="1.6809E-10"
        iyy="0.00098383"
        iyz="5.3327E-09"
        izz="0.00065412" />
    </inertial>
    <visual>
      <origin
        xyz="0 0 0"
        rpy="0 0 0" />
      <geometry>
        <mesh
          filename="../meshes/Body.STL" />
      </geometry>
      <material
        name="">
        <color
          rgba="0.79216 0.81961 0.93333 1" />
      </material>
    </visual>
    <collision>
      <origin
        xyz="0 0 0"
        rpy="0 0 0" />
      <geometry>
        <mesh
          filename="../meshes/Body.STL" />
      </geometry>
    </collision>
  </link>
  <link
    name="Servo1_Left">
    <inertial>
      <origin
        xyz="0.000174801119477867 -0.0318010030269155 6.63024617987469E-05"
        rpy="0 0 0" />
      <mass
        value="0.0230007365895397" />
      <inertia
        ixx="3.38038527155296E-06"
        ixy="2.66636683877595E-09"
        ixz="-8.41838748724041E-11"
        iyy="1.0750315407539E-06"
        iyz="-1.3768348036188E-09"
        izz="2.85194124414614E-06" />
    </inertial>
    <visual>
      <origin
        xyz="0 0 0"
        rpy="0 0 0" />
      <geometry>
        <mesh
          filename="../meshes/Servo1_Left.STL" />
      </geometry>
      <material
        name="">
        <color
          rgba="0.792156862745098 0.819607843137255 0.933333333333333 1" />
      </material>
    </visual>
    <collision>
      <origin
        xyz="0 0 0"
        rpy="0 0 0" />
      <geometry>
        <mesh
          filename="../meshes/Servo1_Left.STL" />
      </geometry>
    </collision>
  </link>
  <joint
    name="hip_L"
    type="revolute">
    <origin
      xyz="0.05 -0.048627 0"
      rpy="0 0 0" />
    <parent
      link="Body" />
    <child
      link="Servo1_Left" />
    <axis
      xyz="0 0 1" />
    <limit
      lower="-1.5708"
      upper="1.5708"
      effort="0.52"
      velocity="10.89" />
  </joint>
  <link
    name="Servo2_Left">
    <inertial>
      <origin
        xyz="0.000235907986100528 -0.0319962115408566 9.42397503334013E-06"
        rpy="0 0 0" />
      <mass
        value="0.022604308352287" />
      <inertia
        ixx="3.27436167088692E-06"
        ixy="2.66811008456606E-09"
        ixz="-8.29162619229438E-11"
        iyy="1.11333471633781E-06"
        iyz="-1.37858113387006E-09"
        izz="2.83878279589868E-06" />
    </inertial>
    <visual>
      <origin
        xyz="0 0 0"
        rpy="0 0 0" />
      <geometry>
        <mesh
          filename="../meshes/Servo2_Left.STL" />
      </geometry>
      <material
        name="">
        <color
          rgba="0.792156862745098 0.819607843137255 0.933333333333333 1" />
      </material>
    </visual>
    <collision>
      <origin
        xyz="0 0 0"
        rpy="0 0 0" />
      <geometry>
        <mesh
          filename="../meshes/Servo2_Left.STL" />
      </geometry>
    </collision>
  </link>
  <joint
    name="knee_L"
    type="revolute">
    <origin
      xyz="0 -0.047416 0"
      rpy="0 0 0" />
    <parent
      link="Servo1_Left" />
    <child
      link="Servo2_Left" />
    <axis
      xyz="-1 0 0" />
    <limit
      lower="-1.5708"
      upper="1.5708"
      effort="0.52"
      velocity="10.89" />
  </joint>
  <link
    name="Servo3_Left">
    <inertial>
      <origin
        xyz="8.14892709387893E-05 -0.0246574562466224 2.80851152929188E-09"
        rpy="0 0 0" />
      <mass
        value="0.0161002375604621" />
      <inertia
        ixx="1.7994604546192E-06"
        ixy="1.24376478044773E-12"
        ixz="6.80558848949548E-14"
        iyy="1.23532312259261E-06"
        iyz="-1.4179313122931E-13"
        izz="1.4738916006442E-06" />
    </inertial>
    <visual>
      <origin
        xyz="0 0 0"
        rpy="0 0 0" />
      <geometry>
        <mesh
          filename="../meshes/Servo3_Left.STL" />
      </geometry>
      <material
        name="">
        <color
          rgba="0.792156862745098 0.819607843137255 0.933333333333333 1" />
      </material>
    </visual>
    <collision>
      <origin
        xyz="0 0 0"
        rpy="0 0 0" />
      <geometry>
        <mesh
          filename="../meshes/Servo3_Left.STL" />
      </geometry>
    </collision>
  </link>
  <joint
    name="ankle_L"
    type="revolute">
    <origin
      xyz="0 -0.047416 0"
      rpy="0 0 0" />
    <parent
      link="Servo2_Left" />
    <child
      link="Servo3_Left" />
    <axis
      xyz="1 0 0" />
    <limit
      lower="-1.5708"
      upper="1.5708"
      effort="0.52"
      velocity="10.89" />
  </joint>
  <link
    name="Servo1_Right">
    <inertial>
      <origin
        xyz="0 0 0"
        rpy="0 0 0" />
      <mass
        value="0" />
      <inertia
        ixx="0"
        ixy="0"
        ixz="0"
        iyy="0"
        iyz="0"
        izz="0" />
    </inertial>
    <visual>
      <origin
        xyz="0 0 0"
        rpy="0 0 0" />
      <geometry>
        <mesh
          filename="../meshes/Servo1_Right.STL" />
      </geometry>
      <material
        name="">
        <color
          rgba="1 1 1 1" />
      </material>
    </visual>
    <collision>
      <origin
        xyz="0 0 0"
        rpy="0 0 0" />
      <geometry>
        <mesh
          filename="../meshes/Servo1_Right.STL" />
      </geometry>
    </collision>
  </link>
  <joint
    name="hip_R"
    type="revolute">
    <origin
      xyz="-0.05 -0.0486271117592205 0"
      rpy="0 0 0" />
    <parent
      link="Body" />
    <child
      link="Servo1_Right" />
    <axis
      xyz="0 0 1" />
    <limit
      lower="-1.5708"
      upper="1.5708"
      effort="0.52"
      velocity="10.89" />
  </joint>
  <link
    name="Servo2_Right">
    <inertial>
      <origin
        xyz="0.000235907986100514 -0.0319962115408566 9.42397503333711E-06"
        rpy="0 0 0" />
      <mass
        value="0.0226043083522871" />
      <inertia
        ixx="3.27436167088692E-06"
        ixy="2.6681100845662E-09"
        ixz="-8.29162619230905E-11"
        iyy="1.11333471633782E-06"
        iyz="-1.37858113386937E-09"
        izz="2.83878279589868E-06" />
    </inertial>
    <visual>
      <origin
        xyz="0 0 0"
        rpy="0 0 0" />
      <geometry>
        <mesh
          filename="../meshes/Servo2_Right.STL" />
      </geometry>
      <material
        name="">
        <color
          rgba="0.792156862745098 0.819607843137255 0.933333333333333 1" />
      </material>
    </visual>
    <collision>
      <origin
        xyz="0 0 0"
        rpy="0 0 0" />
      <geometry>
        <mesh
          filename="../meshes/Servo2_Right.STL" />
      </geometry>
    </collision>
  </link>
  <joint
    name="knee_R"
    type="revolute">
    <origin
      xyz="0 -0.0474161341528266 0"
      rpy="0 0 0" />
    <parent
      link="Servo1_Right" />
    <child
      link="Servo2_Right" />
    <axis
      xyz="-1 0 0" />
    <limit
      lower="-1.5708"
      upper="1.5708"
      effort="0.52"
      velocity="10.89" />
  </joint>
  <link
    name="Servo3_Right">
    <inertial>
      <origin
        xyz="8.14892709387616E-05 -0.0246574562466224 2.80851153634826E-09"
        rpy="0 0 0" />
      <mass
        value="0.0161002375604621" />
      <inertia
        ixx="1.7994604546192E-06"
        ixy="1.24376478041913E-12"
        ixz="6.80558851190484E-14"
        iyy="1.23532312259261E-06"
        iyz="-1.41793131368259E-13"
        izz="1.4738916006442E-06" />
    </inertial>
    <visual>
      <origin
        xyz="0 0 0"
        rpy="0 0 0" />
      <geometry>
        <mesh
          filename="../meshes/Servo3_Right.STL" />
      </geometry>
      <material
        name="">
        <color
          rgba="0.792156862745098 0.819607843137255 0.933333333333333 1" />
      </material>
    </visual>
    <collision>
      <origin
        xyz="0 0 0"
        rpy="0 0 0" />
      <geometry>
        <mesh
          filename="../meshes/Servo3_Right.STL" />
      </geometry>
    </collision>
  </link>
  <joint
    name="ankle_R"
    type="revolute">
    <origin
      xyz="0 -0.0474161341528267 0"
      rpy="0 0 0" />
    <parent
      link="Servo2_Right" />
    <child
      link="Servo3_Right" />
    <axis
      xyz="1 0 0" />
    <limit
      lower="-1.5708"
      upper="1.5708"
      effort="0.52"
      velocity="10.89" />
  </joint>
</robot>